<?xml version="1.0"?>
<!-- This URDF was automatically created by SolidWorks to URDF Exporter! Originally created by Stephen Brawner (brawner@gmail.com) 
     Commit Version: 1.6.0-4-g7f85cfe  Build Version: 1.6.7995.38578
     For more information, please see http://wiki.ros.org/sw_urdf_exporter -->
<robot xmlns:xacro="http://www.ros.org/wiki/xacro"
  name="autobot">
  <link
    name="base_link">
    <inertial>
      <origin
        xyz="0.012692 0.0050409 -0.025738"
        rpy="0 0 0" />
      <mass
        value="0.8044" />
      <inertia
        ixx="0.0026664"
        ixy="1.82E-05"
        ixz="2.9353E-07"
        iyy="0.0015515"
        iyz="6.5283E-11"
        izz="0.0041284" />
    </inertial>
    <visual>
      <origin
        xyz="0 0 0"
        rpy="0 0 0" />
      <geometry>
        <mesh
          filename="package://autobot/meshes/base_link.STL" />
      </geometry>
      <material
        name="">
        <color
          rgba="0.79216 0.81961 0.93333 1" />
      </material>
    </visual>
    <collision>
      <origin
        xyz="0 0 0"
        rpy="0 0 0" />
      <geometry>
        <mesh
          filename="package://autobot/meshes/base_link.STL" />
      </geometry>
    </collision>
  </link>


<link name="right_wheel">
    <inertial>
        <origin xyz="-1.1077E-07 0.0035 -8.1377E-05" rpy="0 0 0" />
        <mass value="0.10364" />
        <inertia ixx="8.7625E-05" ixy="1.349E-18" ixz="-1.8576E-20" iyy="0.00016817" iyz="-3.0937E-19" izz="8.7625E-05" />
    </inertial>
    <visual>
        <origin xyz="0 0 0" rpy="0 0 0" />
        <geometry>
            <mesh filename="package://autobot/meshes/right_wheel.STL" />
        </geometry>
        <material name="">
            <color rgba="0.79608 0.82353 0.93725 1" />
        </material>
    </visual>
    <collision>
        <origin xyz="0 0 0" rpy="0 0 0" />
        <geometry>
            <mesh filename="package://autobot/meshes/right_wheel.STL" />
        </geometry>
    </collision>
</link>

<joint name="right_wheel_joint" type="continuous">
    <origin xyz="-0.016418 -0.18164 -0.079762" rpy="0 0 0" />
    <parent link="base_link" />
    <child link="right_wheel" />
    <axis xyz="0 1 0" /> <!-- Aligned with the y-axis -->
    <limit effort="10" velocity="10" />
    <dynamics damping="0.1" friction="0.1" />
</joint>


 <link name="left_wheel">
    <inertial>
        <origin xyz="-1.534E-06 -0.0035 -8.1363E-05" rpy="0 0 0" />
        <mass value="0.10364" />
        <inertia ixx="8.7625E-05" ixy="1.3327E-18" ixz="2.4026E-21" iyy="0.00016817" iyz="-2.6053E-19" izz="8.7625E-05" />
    </inertial>
    <visual>
        <origin xyz="0 0 0" rpy="0 0 0" />
        <geometry>
            <mesh filename="package://autobot/meshes/left_wheel.STL" />
        </geometry>
        <material name="">
            <color rgba="0.79608 0.82353 0.93725 1" />
        </material>
    </visual>
    <collision>
        <origin xyz="0 0 0" rpy="0 0 0" />
        <geometry>
            <mesh filename="package://autobot/meshes/left_wheel.STL" />
        </geometry>
    </collision>
</link>

<joint name="left_wheel_joint" type="continuous">
    <origin xyz="-0.015294 0.18886 -0.079763" rpy="0 0 0" />
    <parent link="base_link" />
    <child link="left_wheel" />
    <axis xyz="0 1 0" /> <!-- Aligned with the y-axis -->
    <limit effort="10" velocity="10" />
    <dynamics damping="0.1" friction="0.1" />
</joint>


  
 <link name="castor_wheels">
    <inertial>
        <origin xyz="5.5511E-17 7.6762E-16 4.1633E-17" rpy="0 0 0" />
        <mass value="0.4" />
        <inertia ixx="9.1441E-05" ixy="1.239E-18" ixz="3.9667E-21" iyy="0.00018051" iyz="-1.6989E-19" izz="9.1441E-05" />
    </inertial>
    <visual>
        <origin xyz="0 0 0" rpy="0 0 0" />
        <geometry>
            <mesh filename="package://autobot/meshes/castor_wheels.STL" />
        </geometry>
        <material name="">
            <color rgba="0.79216 0.81961 0.93333 1" />
        </material>
    </visual>
    <collision>
        <origin xyz="0 0 0" rpy="0 0 0" />
        <geometry>
            <mesh filename="package://autobot/meshes/castor_wheels.STL" />
        </geometry>
    </collision>
</link>

<joint name="castor_wheels_joint" type="continuous">
    <origin xyz="0.17607 0.003608 -0.079343" rpy="0 0 0" />
    <parent link="base_link" />
    <child link="castor_wheels" />
    <axis xyz="0 1 0" />
    <limit effort="10" velocity="10" />
    <dynamics damping="0.0" friction="0.0"/>

    <gazebo>
        <mu1>0.0</mu1>
        <mu2>0.0</mu2>

        
        <!-- <kp>1000.0</kp>  Optional stiffness coefficient -->
        <!-- <kd>1.0</kd>     Optional damping coefficient -->
        
    </gazebo>
</joint>


  
  <link
    name="camera">
    <inertial>
      <origin
        xyz="0.0012481 5.1998E-08 0.027201"
        rpy="0 0 0" />
      <mass
        value="0.12075" />
      <inertia
        ixx="7.9562E-05"
        ixy="-9.7058E-11"
        ixz="2.8913E-07"
        iyy="3.6327E-05"
        iyz="1.351E-10"
        izz="5.533E-05" />
    </inertial>
    <visual>
      <origin
        xyz="0 0 0"
        rpy="0 0 0" />
      <geometry>
        <mesh
          filename="package://autobot/meshes/camera.STL" />
      </geometry>
      <material
        name="">
        <color
          rgba="1 1 1 1" />
      </material>
    </visual>
    <collision>
      <origin
        xyz="0 0 0"
        rpy="0 0 0" />
      <geometry>
        <mesh
          filename="package://autobot/meshes/camera.STL" />
      </geometry>
    </collision>
  </link>
  <joint
    name="camera_joint"
    type="fixed">
    <origin
      xyz="0.12456 0.003608 -0.035343"
      rpy="0 0 0" />
    <parent
      link="base_link" />
    <child
      link="camera" />
    <axis
      xyz="0 0 0" />
  </joint>
</robot>